Arguments: Namespace(finit='00,06,12,18', flen=30, out_dir='/perm/ms/dk/nhd/carra_merge_vfld', period='19980229-19980229', vfld_dir='/scratch/ms/dk/nhz/oprint/')
/perm/ms/dk/nhd/carra_merge_vfld directory already exists!
All screen output will be written to /perm/ms/dk/nhd/carra_merge_vfld/merge.log
Traceback (most recent call last):
  File "./merge_carra_vfld.py", line 147, in <module>
    igb = vf(model='carra_IGB', period=period, finit=finit, flen=21, datadir=datadir)
  File "/gpfs/ecgb/perm/ms/dk/nhd/scripts_verif/merge_scripts/merge_vfld/vfld.py", line 36, in __init__
    ifiles_model,dates_model = self._locate_files(self.datadir,self.model,self.period,self.finit,self.flen)
  File "/gpfs/ecgb/perm/ms/dk/nhd/scripts_verif/merge_scripts/merge_vfld/vfld.py", line 102, in _locate_files
    date_ini=datetime.datetime.strptime(period[0],'%Y%m%d')
  File "/perm/ms/dk/nhd/miniconda3/envs/py37/lib/python3.7/_strptime.py", line 577, in _strptime_datetime
    tt, fraction, gmtoff_fraction = _strptime(data_string, format)
  File "/perm/ms/dk/nhd/miniconda3/envs/py37/lib/python3.7/_strptime.py", line 544, in _strptime
    datetime_date(year, 1, 1).toordinal() + 1
ValueError: day is out of range for month
